
<?xml version="1.0"?>
<robot xmlns:xacro="http://www.ros.org/wiki/xacro" name="rover">


<link name="base_footprint">
    
</link>

<link name="base_link">
    <visual>
        <origin xyz="0.0 0.0 0.0" rpy="0.0 0.0 0.0"/>
        <geometry>
            <box size="0.75 0.6 0.1" />
        </geometry>
        <material name="LightGrey">
            <color rgba="0.9 0.7 0.7 1.0"/>
        </material>
    </visual>
    <collision>
        <geometry>  
            <box size="0.75 0.4 0.1" />
        </geometry>
    </collision>
    <inertial>
        <mass value="0.0"/>
        <origin xyz="0.0 0.0 0.0" rpy="0.0 0.0 0.0"/>
        <inertia ixx="0.0" ixy="0.0" ixz="0.0" iyy="0.0" iyz="0.0" izz="0.0"/>
    </inertial>
</link>

<joint name="base_joint" type="fixed">
    <parent link="base_footprint"/>
    <child link="base_link"/>
    <origin xyz="0 0 0.135" rpy="0 0 0"/>
    <axis xyz="0 0 0"/>
</joint>



<!--Front right wheel -->
<xacro:property name="side" value="front_right"/>
<link name="wheel_${side}_link">
    <visual>
        <origin xyz="0.0 0.0 0.0" rpy="0.0 0.0 0.0"/>
        
        <geometry>
            <cylinder radius="0.15" length="0.1"/>
        </geometry>
        <material name="a">
            <color rgba="0.5 0.2 0.7 1.0"/>
        </material>
    </visual>
    <collision>
        <origin xyz="0.0 0.0 0.0" rpy="0.0 0.0 0.0"/>
        <geometry>
            <cylinder radius="0.15" length="0.1"/>
        </geometry>
    </collision>
    <inertial>
        <mass value="0.5"/>
        <origin xyz="0.0 0.0 0.0" rpy="0.0 0.0 0.0"/>
        <inertia ixx="0.0" ixy="0.0" ixz="0.0" iyy="0.0" iyz="0.0" izz="0.0"/>
    </inertial>
</link>

<joint name="wheel_${side}_joint" type="continuous">
    <parent link="base_link"/>
    <child link="wheel_${side}_link"/>
    <origin xyz="0.250 0.4 0" rpy="1.57 0 0"/>
    <axis xyz="0 0 1"/>
</joint>



<!--Front left wheel -->

<link name="wheel_front_left_link">
    <visual>
        <origin xyz="0.0 0.0 0.0" rpy="0.0 0.0 0.0"/>
    
        <geometry>
            <cylinder radius="0.15" length="0.1"/>
        </geometry>
        <material name="a">
            <color rgba="0.5 0.2 0.7 1.0"/>
        </material>
    </visual>
    <collision>
        <origin xyz="0.0 0.0 0.0" rpy="0.0 0.0 0.0"/>
        <geometry>
            <cylinder radius="0.15" length="0.1"/>
        </geometry>
    </collision>
    <inertial>
        <mass value="0.0"/>
        <origin xyz="0.0 0.0 0.0" rpy="0.0 0.0 0.0"/>
        <inertia ixx="0.0" ixy="0.0" ixz="0.0" iyy="0.0" iyz="0.0" izz="0.0"/>
    </inertial>
</link>
<joint name="joint_fl" type="continuous">
    <parent link="base_link"/>
    <child link="wheel_front_left"/>
    <origin xyz="0.250 -0.4 0" rpy="1.57 0 0"/>
    <axis xyz="0 0 1"/>
</joint>

<!--rear right wheel -->
<link name="wheel_rear_right">
    <visual>
        <origin xyz="0.0 0.0 0.0" rpy="0.0 0.0 0.0"/>
    
        <geometry>
            <cylinder radius="0.15" length="0.1"/>
        </geometry>
        <material name="a">
            <color rgba="0.5 0.2 0.7 1.0"/>
        </material>
    </visual>
    <collision>
        <origin xyz="0.0 0.0 0.0" rpy="0.0 0.0 0.0"/>
        <geometry>
            <cylinder radius="0.15" length="0.1"/>
        </geometry>
    </collision>
    <inertial>
        <mass value="0.0"/>
        <origin xyz="0.0 0.0 0.0" rpy="0.0 0.0 0.0"/>
        <inertia ixx="0.0" ixy="0.0" ixz="0.0" iyy="0.0" iyz="0.0" izz="0.0"/>
    </inertial>
</link>
<joint name="joint_rr" type="continuous">
    <parent link="base_link"/>
    <child link="wheel_rear_right"/>
    <origin xyz="-0.250 0.4 0" rpy="1.57 0 0"/>
    <axis xyz="0 0 1"/>
</joint>

<!--Front left wheel -->
<link name="wheel_rear_left">
    <visual>
        <origin xyz="0.0 0.0 0.0" rpy="0.0 0.0 0.0"/>
    
        <geometry>
            <cylinder radius="0.15" length="0.1"/>
        </geometry>
        <material name="a">
            <color rgba="0.5 0.2 0.7 1.0"/>
        </material>
    </visual>
    <collision>
        <origin xyz="0.0 0.0 0.0" rpy="0.0 0.0 0.0"/>
        <geometry>
            <cylinder radius="0.15" length="0.1"/>
        </geometry>
    </collision>
    <inertial>
        <mass value="0.0"/>
        <origin xyz="0.0 0.0 0.0" rpy="0.0 0.0 0.0"/>
        <inertia ixx="0.0" ixy="0.0" ixz="0.0" iyy="0.0" iyz="0.0" izz="0.0"/>
    </inertial>
</link>
<joint name="joint_rl" type="continuous">
    <parent link="base_link"/>
    <child link="wheel_rear_left"/>
    <origin xyz="-0.250 -0.4 0" rpy="1.57 0 0"/>
    <axis xyz="0 0 1"/>
</joint>

<xacro:property name="side" value="front_left"/>

</robot>
