<?xml version="1.0"?>
<robot xmlns:xacro="http://www.ros.org/wiki/xacro" name="rover">



<link name="base_footprint"/>

<xacro:property name="constant" value="1/12"/>
<xacro:property name="mass" value="1.0"/>
<xacro:property name="height" value="0.1"/>
<xacro:property name="width" value="0.8"/>
<xacro:property name="depth" value="0.7"/>


<link name="base_link">
    <inertial>
        <origin xyz="0.0 0.0 0.0" rpy="0.0 0.0 0.0"/>
        <mass value="2.0"/>
        <inertia ixx="0.082" ixy="0.0" ixz="0.0"
                 iyy="0.108" iyz="0.0"
                 izz="0.188"/>
    </inertial>
    <visual name="">
        <origin xyz="0.0 0.0 0.0" rpy="0.0 0.0 0.0"/>
        <geometry>
            <box size="0.8 0.6 0.1"/>
        </geometry>
        <material name="">
            <color rgba="1.0 0.0 0.0 1.0"/>
            <texture filename=""/>
        </material>
    </visual>
    <collision>
        <origin xyz="0.0 0.0 0.0" rpy="0.0 0.0 0.0"/>
        <geometry>
            <box size="0.0 0.0 0.0"/>
        </geometry>
    </collision>
</link>

<joint name="base_joint" type="fixed">
    <origin xyz="0.0 0.0 0.135" rpy="0.0 0.0 0.0"/>
    <parent link="base_footprint"/>
    <child link="base_link"/>
    <axis xyz="0.0 0.0 0.0"/>
</joint>
<gazebo reference="base_link">
<material>Gazebo/Red</material>
</gazebo>


<xacro:include filename="$(find mobile_robot)/urdf/lidar.xacro" />
<!-- All Wheel links and joints -->
<xacro:macro name="wheel" params="name x y">

    <link name="wheel_${name}_link">
        <inertial>
            <origin xyz="0.0 0.0 0.0" rpy="0.0 0.0 0.0"/>
            <mass value="0.05"/>
            <inertia ixx="0.004375" ixy="0.0" ixz="0.0" iyy="0.00875" iyz="0.0" izz="0.004375"/>
        </inertial>
        <visual name="">
            <origin xyz="0.0 0.0 0.0" rpy="0.0 0.0 0.0"/>
            <geometry>
                <mesh filename="package://mobile_robot/meshes/left_tire.stl" scale="0.005 0.005 0.005"/>
            </geometry>
            <material name="black">
                <color rgba=".0 .0 0.0 1.0"/>
            </material>
        </visual>
        <collision>
            <origin xyz="0.0 0.0 0.0" rpy="0.0 0.0 0.0"/>
            <geometry>
                <mesh filename="package://mobile_robot/meshes/left_tire.stl" scale="0.005 0.005 0.005"/>
            </geometry>
        </collision>
    </link>

    <joint name="wheel_${name}_joint" type="continuous">
        <origin xyz="${x} ${y} .0" rpy="0 0.0 0.0"/>
        <parent link="base_link"/>
        <child link="wheel_${name}_link"/>
        <axis xyz=".0 1.0 .0"/>
    </joint>

    <gazebo reference="wheel_${name}_link">
    <material>Gazebo/Black</material>
    </gazebo>



</xacro:macro>


<!-- Wheel Creating using macros -->
<xacro:wheel name="rear_right"  x="0.250" y =" 0.40"/>
<xacro:wheel name="front_right" x="-0.250" y =" 0.40"/>
<xacro:wheel name="front_left"  x="-0.250" y =" -0.40"/>
<xacro:wheel name="rear_left"   x="0.250" y =" -0.40"/>

<gazebo>
  <plugin name="skid_steer_drive_controller" filename="libgazebo_ros_skid_steer_drive.so">
    <updateRate>10.0</updateRate>
    <robotNamespace>/</robotNamespace>
    <leftFrontJoint>wheel_front_left_joint</leftFrontJoint>
    <rightFrontJoint>wheel_front_right_joint</rightFrontJoint>
    <leftRearJoint>wheel_rear_left_joint</leftRearJoint>
    <rightRearJoint>wheel_rear_right_joint</rightRearJoint>
    <wheelSeparation>0.5</wheelSeparation>
    <wheelDiameter>0.35</wheelDiameter>
    <robotBaseFrame>base_link</robotBaseFrame>
    <torque>3</torque>
    <topicName>cmd_vel</topicName>
    <broadcastTF>true</broadcastTF>
  </plugin>
</gazebo>




</robot>